[2025-01-23T09:22:51.068+0000] {scheduler_job_runner.py:781} ERROR - Executor reports task instance <TaskInstance: etl_process.start_dag scheduled__2025-01-21T22:00:00+00:00 [queued]> finished (failed) although the task says it's queued. (Info: None) Was the task killed externally?
