[2025-01-20T14:39:51.090+0000] {processor.py:161} INFO - Started process (PID=16881) to work on /opt/airflow/dags/etl_process.py
[2025-01-20T14:39:51.093+0000] {processor.py:830} INFO - Processing file /opt/airflow/dags/etl_process.py for tasks to queue
[2025-01-20T14:39:51.107+0000] {logging_mixin.py:188} INFO - [2025-01-20T14:39:51.106+0000] {dagbag.py:538} INFO - Filling up the DagBag from /opt/airflow/dags/etl_process.py
[2025-01-20T14:39:51.179+0000] {logging_mixin.py:188} INFO - [2025-01-20T14:39:51.174+0000] {dagbag.py:348} ERROR - Failed to import: /opt/airflow/dags/etl_process.py
Traceback (most recent call last):
  File "/home/airflow/.local/lib/python3.8/site-packages/airflow/models/dagbag.py", line 344, in parse
    loader.exec_module(new_module)
  File "<frozen importlib._bootstrap_external>", line 839, in exec_module
  File "<frozen importlib._bootstrap_external>", line 976, in get_code
  File "<frozen importlib._bootstrap_external>", line 906, in source_to_code
  File "<frozen importlib._bootstrap>", line 219, in _call_with_frames_removed
  File "/opt/airflow/dags/etl_process.py", line 17
    dag_id:f'etl_process',
          ^
SyntaxError: invalid syntax
[2025-01-20T14:39:51.184+0000] {processor.py:842} WARNING - No viable dags retrieved from /opt/airflow/dags/etl_process.py
[2025-01-20T14:39:51.276+0000] {processor.py:183} INFO - Processing /opt/airflow/dags/etl_process.py took 0.201 seconds
[2025-01-20T14:40:21.376+0000] {processor.py:161} INFO - Started process (PID=16937) to work on /opt/airflow/dags/etl_process.py
[2025-01-20T14:40:21.378+0000] {processor.py:830} INFO - Processing file /opt/airflow/dags/etl_process.py for tasks to queue
[2025-01-20T14:40:21.382+0000] {logging_mixin.py:188} INFO - [2025-01-20T14:40:21.381+0000] {dagbag.py:538} INFO - Filling up the DagBag from /opt/airflow/dags/etl_process.py
[2025-01-20T14:40:21.403+0000] {logging_mixin.py:188} INFO - [2025-01-20T14:40:21.402+0000] {dagbag.py:348} ERROR - Failed to import: /opt/airflow/dags/etl_process.py
Traceback (most recent call last):
  File "/home/airflow/.local/lib/python3.8/site-packages/airflow/models/dagbag.py", line 344, in parse
    loader.exec_module(new_module)
  File "<frozen importlib._bootstrap_external>", line 839, in exec_module
  File "<frozen importlib._bootstrap_external>", line 976, in get_code
  File "<frozen importlib._bootstrap_external>", line 906, in source_to_code
  File "<frozen importlib._bootstrap>", line 219, in _call_with_frames_removed
  File "/opt/airflow/dags/etl_process.py", line 17
    dag_id:f'etl_process',
          ^
SyntaxError: invalid syntax
[2025-01-20T14:40:21.404+0000] {processor.py:842} WARNING - No viable dags retrieved from /opt/airflow/dags/etl_process.py
[2025-01-20T14:40:21.431+0000] {processor.py:183} INFO - Processing /opt/airflow/dags/etl_process.py took 0.059 seconds
[2025-01-20T14:40:52.278+0000] {processor.py:161} INFO - Started process (PID=16994) to work on /opt/airflow/dags/etl_process.py
[2025-01-20T14:40:52.281+0000] {processor.py:830} INFO - Processing file /opt/airflow/dags/etl_process.py for tasks to queue
[2025-01-20T14:40:52.286+0000] {logging_mixin.py:188} INFO - [2025-01-20T14:40:52.286+0000] {dagbag.py:538} INFO - Filling up the DagBag from /opt/airflow/dags/etl_process.py
[2025-01-20T14:40:52.308+0000] {logging_mixin.py:188} INFO - [2025-01-20T14:40:52.306+0000] {dagbag.py:348} ERROR - Failed to import: /opt/airflow/dags/etl_process.py
Traceback (most recent call last):
  File "/home/airflow/.local/lib/python3.8/site-packages/airflow/models/dagbag.py", line 344, in parse
    loader.exec_module(new_module)
  File "<frozen importlib._bootstrap_external>", line 839, in exec_module
  File "<frozen importlib._bootstrap_external>", line 976, in get_code
  File "<frozen importlib._bootstrap_external>", line 906, in source_to_code
  File "<frozen importlib._bootstrap>", line 219, in _call_with_frames_removed
  File "/opt/airflow/dags/etl_process.py", line 17
    dag_id:f'etl_process',
          ^
SyntaxError: invalid syntax
[2025-01-20T14:40:52.309+0000] {processor.py:842} WARNING - No viable dags retrieved from /opt/airflow/dags/etl_process.py
[2025-01-20T14:40:52.354+0000] {processor.py:183} INFO - Processing /opt/airflow/dags/etl_process.py took 0.084 seconds
[2025-01-20T14:41:06.738+0000] {processor.py:161} INFO - Started process (PID=17019) to work on /opt/airflow/dags/etl_process.py
[2025-01-20T14:41:06.741+0000] {processor.py:830} INFO - Processing file /opt/airflow/dags/etl_process.py for tasks to queue
[2025-01-20T14:41:06.746+0000] {logging_mixin.py:188} INFO - [2025-01-20T14:41:06.745+0000] {dagbag.py:538} INFO - Filling up the DagBag from /opt/airflow/dags/etl_process.py
[2025-01-20T14:41:06.771+0000] {logging_mixin.py:188} INFO - [2025-01-20T14:41:06.769+0000] {dagbag.py:348} ERROR - Failed to import: /opt/airflow/dags/etl_process.py
Traceback (most recent call last):
  File "/home/airflow/.local/lib/python3.8/site-packages/airflow/models/dagbag.py", line 344, in parse
    loader.exec_module(new_module)
  File "<frozen importlib._bootstrap_external>", line 839, in exec_module
  File "<frozen importlib._bootstrap_external>", line 976, in get_code
  File "<frozen importlib._bootstrap_external>", line 906, in source_to_code
  File "<frozen importlib._bootstrap>", line 219, in _call_with_frames_removed
  File "/opt/airflow/dags/etl_process.py", line 19
    dag_id:f'etl_process',
          ^
SyntaxError: invalid syntax
[2025-01-20T14:41:06.772+0000] {processor.py:842} WARNING - No viable dags retrieved from /opt/airflow/dags/etl_process.py
[2025-01-20T14:41:06.814+0000] {processor.py:183} INFO - Processing /opt/airflow/dags/etl_process.py took 0.084 seconds
[2025-01-20T14:41:36.988+0000] {processor.py:161} INFO - Started process (PID=17074) to work on /opt/airflow/dags/etl_process.py
[2025-01-20T14:41:36.990+0000] {processor.py:830} INFO - Processing file /opt/airflow/dags/etl_process.py for tasks to queue
[2025-01-20T14:41:36.996+0000] {logging_mixin.py:188} INFO - [2025-01-20T14:41:36.995+0000] {dagbag.py:538} INFO - Filling up the DagBag from /opt/airflow/dags/etl_process.py
[2025-01-20T14:41:37.022+0000] {logging_mixin.py:188} INFO - [2025-01-20T14:41:37.020+0000] {dagbag.py:348} ERROR - Failed to import: /opt/airflow/dags/etl_process.py
Traceback (most recent call last):
  File "/home/airflow/.local/lib/python3.8/site-packages/airflow/models/dagbag.py", line 344, in parse
    loader.exec_module(new_module)
  File "<frozen importlib._bootstrap_external>", line 839, in exec_module
  File "<frozen importlib._bootstrap_external>", line 976, in get_code
  File "<frozen importlib._bootstrap_external>", line 906, in source_to_code
  File "<frozen importlib._bootstrap>", line 219, in _call_with_frames_removed
  File "/opt/airflow/dags/etl_process.py", line 19
    dag_id:f'etl_process',
          ^
SyntaxError: invalid syntax
[2025-01-20T14:41:37.023+0000] {processor.py:842} WARNING - No viable dags retrieved from /opt/airflow/dags/etl_process.py
[2025-01-20T14:41:37.132+0000] {processor.py:183} INFO - Processing /opt/airflow/dags/etl_process.py took 0.153 seconds
[2025-01-20T14:42:07.414+0000] {processor.py:161} INFO - Started process (PID=17130) to work on /opt/airflow/dags/etl_process.py
[2025-01-20T14:42:07.415+0000] {processor.py:830} INFO - Processing file /opt/airflow/dags/etl_process.py for tasks to queue
[2025-01-20T14:42:07.418+0000] {logging_mixin.py:188} INFO - [2025-01-20T14:42:07.418+0000] {dagbag.py:538} INFO - Filling up the DagBag from /opt/airflow/dags/etl_process.py
[2025-01-20T14:42:07.439+0000] {logging_mixin.py:188} INFO - [2025-01-20T14:42:07.438+0000] {dagbag.py:348} ERROR - Failed to import: /opt/airflow/dags/etl_process.py
Traceback (most recent call last):
  File "/home/airflow/.local/lib/python3.8/site-packages/airflow/models/dagbag.py", line 344, in parse
    loader.exec_module(new_module)
  File "<frozen importlib._bootstrap_external>", line 839, in exec_module
  File "<frozen importlib._bootstrap_external>", line 976, in get_code
  File "<frozen importlib._bootstrap_external>", line 906, in source_to_code
  File "<frozen importlib._bootstrap>", line 219, in _call_with_frames_removed
  File "/opt/airflow/dags/etl_process.py", line 19
    dag_id:f'etl_process',
          ^
SyntaxError: invalid syntax
[2025-01-20T14:42:07.440+0000] {processor.py:842} WARNING - No viable dags retrieved from /opt/airflow/dags/etl_process.py
[2025-01-20T14:42:07.471+0000] {processor.py:183} INFO - Processing /opt/airflow/dags/etl_process.py took 0.062 seconds
[2025-01-20T14:42:36.267+0000] {processor.py:161} INFO - Started process (PID=17181) to work on /opt/airflow/dags/etl_process.py
[2025-01-20T14:42:36.271+0000] {processor.py:830} INFO - Processing file /opt/airflow/dags/etl_process.py for tasks to queue
[2025-01-20T14:42:36.276+0000] {logging_mixin.py:188} INFO - [2025-01-20T14:42:36.275+0000] {dagbag.py:538} INFO - Filling up the DagBag from /opt/airflow/dags/etl_process.py
[2025-01-20T14:42:36.300+0000] {logging_mixin.py:188} INFO - [2025-01-20T14:42:36.298+0000] {dagbag.py:348} ERROR - Failed to import: /opt/airflow/dags/etl_process.py
Traceback (most recent call last):
  File "/home/airflow/.local/lib/python3.8/site-packages/airflow/models/dagbag.py", line 344, in parse
    loader.exec_module(new_module)
  File "<frozen importlib._bootstrap_external>", line 839, in exec_module
  File "<frozen importlib._bootstrap_external>", line 976, in get_code
  File "<frozen importlib._bootstrap_external>", line 906, in source_to_code
  File "<frozen importlib._bootstrap>", line 219, in _call_with_frames_removed
  File "/opt/airflow/dags/etl_process.py", line 29
    python_callable=call,
    ^
SyntaxError: invalid syntax
[2025-01-20T14:42:36.301+0000] {processor.py:842} WARNING - No viable dags retrieved from /opt/airflow/dags/etl_process.py
[2025-01-20T14:42:36.338+0000] {processor.py:183} INFO - Processing /opt/airflow/dags/etl_process.py took 0.080 seconds
[2025-01-20T14:43:06.763+0000] {processor.py:161} INFO - Started process (PID=17235) to work on /opt/airflow/dags/etl_process.py
[2025-01-20T14:43:06.765+0000] {processor.py:830} INFO - Processing file /opt/airflow/dags/etl_process.py for tasks to queue
[2025-01-20T14:43:06.769+0000] {logging_mixin.py:188} INFO - [2025-01-20T14:43:06.768+0000] {dagbag.py:538} INFO - Filling up the DagBag from /opt/airflow/dags/etl_process.py
[2025-01-20T14:43:06.791+0000] {logging_mixin.py:188} INFO - [2025-01-20T14:43:06.789+0000] {dagbag.py:348} ERROR - Failed to import: /opt/airflow/dags/etl_process.py
Traceback (most recent call last):
  File "/home/airflow/.local/lib/python3.8/site-packages/airflow/models/dagbag.py", line 344, in parse
    loader.exec_module(new_module)
  File "<frozen importlib._bootstrap_external>", line 839, in exec_module
  File "<frozen importlib._bootstrap_external>", line 976, in get_code
  File "<frozen importlib._bootstrap_external>", line 906, in source_to_code
  File "<frozen importlib._bootstrap>", line 219, in _call_with_frames_removed
  File "/opt/airflow/dags/etl_process.py", line 29
    python_callable=call,
    ^
SyntaxError: invalid syntax
[2025-01-20T14:43:06.792+0000] {processor.py:842} WARNING - No viable dags retrieved from /opt/airflow/dags/etl_process.py
[2025-01-20T14:43:06.827+0000] {processor.py:183} INFO - Processing /opt/airflow/dags/etl_process.py took 0.070 seconds
[2025-01-20T14:43:08.781+0000] {processor.py:161} INFO - Started process (PID=17242) to work on /opt/airflow/dags/etl_process.py
[2025-01-20T14:43:08.788+0000] {processor.py:830} INFO - Processing file /opt/airflow/dags/etl_process.py for tasks to queue
[2025-01-20T14:43:08.801+0000] {logging_mixin.py:188} INFO - [2025-01-20T14:43:08.799+0000] {dagbag.py:538} INFO - Filling up the DagBag from /opt/airflow/dags/etl_process.py
[2025-01-20T14:43:08.848+0000] {logging_mixin.py:188} INFO - [2025-01-20T14:43:08.846+0000] {dagbag.py:348} ERROR - Failed to import: /opt/airflow/dags/etl_process.py
Traceback (most recent call last):
  File "/home/airflow/.local/lib/python3.8/site-packages/airflow/models/dagbag.py", line 344, in parse
    loader.exec_module(new_module)
  File "<frozen importlib._bootstrap_external>", line 839, in exec_module
  File "<frozen importlib._bootstrap_external>", line 976, in get_code
  File "<frozen importlib._bootstrap_external>", line 906, in source_to_code
  File "<frozen importlib._bootstrap>", line 219, in _call_with_frames_removed
  File "/opt/airflow/dags/etl_process.py", line 29
    python_callable=call,
    ^
SyntaxError: invalid syntax
[2025-01-20T14:43:08.850+0000] {processor.py:842} WARNING - No viable dags retrieved from /opt/airflow/dags/etl_process.py
[2025-01-20T14:43:08.896+0000] {processor.py:183} INFO - Processing /opt/airflow/dags/etl_process.py took 0.135 seconds
[2025-01-20T14:43:20.963+0000] {processor.py:161} INFO - Started process (PID=17273) to work on /opt/airflow/dags/etl_process.py
[2025-01-20T14:43:20.969+0000] {processor.py:830} INFO - Processing file /opt/airflow/dags/etl_process.py for tasks to queue
[2025-01-20T14:43:20.986+0000] {logging_mixin.py:188} INFO - [2025-01-20T14:43:20.985+0000] {dagbag.py:538} INFO - Filling up the DagBag from /opt/airflow/dags/etl_process.py
[2025-01-20T14:43:21.318+0000] {logging_mixin.py:188} INFO - [2025-01-20T14:43:21.300+0000] {dagbag.py:348} ERROR - Failed to import: /opt/airflow/dags/etl_process.py
Traceback (most recent call last):
  File "/home/airflow/.local/lib/python3.8/site-packages/airflow/models/dagbag.py", line 344, in parse
    loader.exec_module(new_module)
  File "<frozen importlib._bootstrap_external>", line 843, in exec_module
  File "<frozen importlib._bootstrap>", line 219, in _call_with_frames_removed
  File "/opt/airflow/dags/etl_process.py", line 1, in <module>
    from datetime import datetime, timedate
ImportError: cannot import name 'timedate' from 'datetime' (/usr/local/lib/python3.8/datetime.py)
[2025-01-20T14:43:21.327+0000] {processor.py:842} WARNING - No viable dags retrieved from /opt/airflow/dags/etl_process.py
[2025-01-20T14:43:21.443+0000] {processor.py:183} INFO - Processing /opt/airflow/dags/etl_process.py took 0.508 seconds
[2025-01-20T14:43:40.937+0000] {processor.py:161} INFO - Started process (PID=17299) to work on /opt/airflow/dags/etl_process.py
[2025-01-20T14:43:40.945+0000] {processor.py:830} INFO - Processing file /opt/airflow/dags/etl_process.py for tasks to queue
[2025-01-20T14:43:40.958+0000] {logging_mixin.py:188} INFO - [2025-01-20T14:43:40.957+0000] {dagbag.py:538} INFO - Filling up the DagBag from /opt/airflow/dags/etl_process.py
[2025-01-20T14:43:41.196+0000] {logging_mixin.py:188} INFO - [2025-01-20T14:43:41.184+0000] {dagbag.py:348} ERROR - Failed to import: /opt/airflow/dags/etl_process.py
Traceback (most recent call last):
  File "/home/airflow/.local/lib/python3.8/site-packages/airflow/models/dagbag.py", line 344, in parse
    loader.exec_module(new_module)
  File "<frozen importlib._bootstrap_external>", line 843, in exec_module
  File "<frozen importlib._bootstrap>", line 219, in _call_with_frames_removed
  File "/opt/airflow/dags/etl_process.py", line 1, in <module>
    from datetime import datetime, timedate
ImportError: cannot import name 'timedate' from 'datetime' (/usr/local/lib/python3.8/datetime.py)
[2025-01-20T14:43:41.200+0000] {processor.py:842} WARNING - No viable dags retrieved from /opt/airflow/dags/etl_process.py
[2025-01-20T14:43:41.295+0000] {processor.py:183} INFO - Processing /opt/airflow/dags/etl_process.py took 0.379 seconds
[2025-01-20T14:44:05.430+0000] {processor.py:161} INFO - Started process (PID=17347) to work on /opt/airflow/dags/etl_process.py
[2025-01-20T14:44:05.434+0000] {processor.py:830} INFO - Processing file /opt/airflow/dags/etl_process.py for tasks to queue
[2025-01-20T14:44:05.441+0000] {logging_mixin.py:188} INFO - [2025-01-20T14:44:05.440+0000] {dagbag.py:538} INFO - Filling up the DagBag from /opt/airflow/dags/etl_process.py
[2025-01-20T14:44:05.503+0000] {logging_mixin.py:188} INFO - [2025-01-20T14:44:05.494+0000] {dagbag.py:348} ERROR - Failed to import: /opt/airflow/dags/etl_process.py
Traceback (most recent call last):
  File "/home/airflow/.local/lib/python3.8/site-packages/airflow/models/dagbag.py", line 344, in parse
    loader.exec_module(new_module)
  File "<frozen importlib._bootstrap_external>", line 843, in exec_module
  File "<frozen importlib._bootstrap>", line 219, in _call_with_frames_removed
  File "/opt/airflow/dags/etl_process.py", line 1, in <module>
    from datetime import datetime, timedate
ImportError: cannot import name 'timedate' from 'datetime' (/usr/local/lib/python3.8/datetime.py)
[2025-01-20T14:44:05.506+0000] {processor.py:842} WARNING - No viable dags retrieved from /opt/airflow/dags/etl_process.py
[2025-01-20T14:44:05.551+0000] {processor.py:183} INFO - Processing /opt/airflow/dags/etl_process.py took 0.134 seconds
[2025-01-20T14:44:36.288+0000] {processor.py:161} INFO - Started process (PID=17403) to work on /opt/airflow/dags/etl_process.py
[2025-01-20T14:44:36.289+0000] {processor.py:830} INFO - Processing file /opt/airflow/dags/etl_process.py for tasks to queue
[2025-01-20T14:44:36.293+0000] {logging_mixin.py:188} INFO - [2025-01-20T14:44:36.293+0000] {dagbag.py:538} INFO - Filling up the DagBag from /opt/airflow/dags/etl_process.py
[2025-01-20T14:44:36.319+0000] {logging_mixin.py:188} INFO - [2025-01-20T14:44:36.314+0000] {dagbag.py:348} ERROR - Failed to import: /opt/airflow/dags/etl_process.py
Traceback (most recent call last):
  File "/home/airflow/.local/lib/python3.8/site-packages/airflow/models/dagbag.py", line 344, in parse
    loader.exec_module(new_module)
  File "<frozen importlib._bootstrap_external>", line 843, in exec_module
  File "<frozen importlib._bootstrap>", line 219, in _call_with_frames_removed
  File "/opt/airflow/dags/etl_process.py", line 1, in <module>
    from datetime import datetime, timedate
ImportError: cannot import name 'timedate' from 'datetime' (/usr/local/lib/python3.8/datetime.py)
[2025-01-20T14:44:36.320+0000] {processor.py:842} WARNING - No viable dags retrieved from /opt/airflow/dags/etl_process.py
[2025-01-20T14:44:36.347+0000] {processor.py:183} INFO - Processing /opt/airflow/dags/etl_process.py took 0.064 seconds
[2025-01-20T14:45:06.715+0000] {processor.py:161} INFO - Started process (PID=17459) to work on /opt/airflow/dags/etl_process.py
[2025-01-20T14:45:06.717+0000] {processor.py:830} INFO - Processing file /opt/airflow/dags/etl_process.py for tasks to queue
[2025-01-20T14:45:06.720+0000] {logging_mixin.py:188} INFO - [2025-01-20T14:45:06.720+0000] {dagbag.py:538} INFO - Filling up the DagBag from /opt/airflow/dags/etl_process.py
[2025-01-20T14:45:06.744+0000] {logging_mixin.py:188} INFO - [2025-01-20T14:45:06.739+0000] {dagbag.py:348} ERROR - Failed to import: /opt/airflow/dags/etl_process.py
Traceback (most recent call last):
  File "/home/airflow/.local/lib/python3.8/site-packages/airflow/models/dagbag.py", line 344, in parse
    loader.exec_module(new_module)
  File "<frozen importlib._bootstrap_external>", line 843, in exec_module
  File "<frozen importlib._bootstrap>", line 219, in _call_with_frames_removed
  File "/opt/airflow/dags/etl_process.py", line 1, in <module>
    from datetime import datetime, timedate
ImportError: cannot import name 'timedate' from 'datetime' (/usr/local/lib/python3.8/datetime.py)
[2025-01-20T14:45:06.745+0000] {processor.py:842} WARNING - No viable dags retrieved from /opt/airflow/dags/etl_process.py
[2025-01-20T14:45:06.769+0000] {processor.py:183} INFO - Processing /opt/airflow/dags/etl_process.py took 0.058 seconds
[2025-01-20T14:45:37.473+0000] {processor.py:161} INFO - Started process (PID=17516) to work on /opt/airflow/dags/etl_process.py
[2025-01-20T14:45:37.474+0000] {processor.py:830} INFO - Processing file /opt/airflow/dags/etl_process.py for tasks to queue
[2025-01-20T14:45:37.478+0000] {logging_mixin.py:188} INFO - [2025-01-20T14:45:37.477+0000] {dagbag.py:538} INFO - Filling up the DagBag from /opt/airflow/dags/etl_process.py
[2025-01-20T14:45:37.505+0000] {logging_mixin.py:188} INFO - [2025-01-20T14:45:37.499+0000] {dagbag.py:348} ERROR - Failed to import: /opt/airflow/dags/etl_process.py
Traceback (most recent call last):
  File "/home/airflow/.local/lib/python3.8/site-packages/airflow/models/dagbag.py", line 344, in parse
    loader.exec_module(new_module)
  File "<frozen importlib._bootstrap_external>", line 843, in exec_module
  File "<frozen importlib._bootstrap>", line 219, in _call_with_frames_removed
  File "/opt/airflow/dags/etl_process.py", line 1, in <module>
    from datetime import datetime, timedate
ImportError: cannot import name 'timedate' from 'datetime' (/usr/local/lib/python3.8/datetime.py)
[2025-01-20T14:45:37.507+0000] {processor.py:842} WARNING - No viable dags retrieved from /opt/airflow/dags/etl_process.py
[2025-01-20T14:45:37.532+0000] {processor.py:183} INFO - Processing /opt/airflow/dags/etl_process.py took 0.063 seconds
[2025-01-20T14:46:07.862+0000] {processor.py:161} INFO - Started process (PID=17572) to work on /opt/airflow/dags/etl_process.py
[2025-01-20T14:46:07.865+0000] {processor.py:830} INFO - Processing file /opt/airflow/dags/etl_process.py for tasks to queue
[2025-01-20T14:46:07.869+0000] {logging_mixin.py:188} INFO - [2025-01-20T14:46:07.869+0000] {dagbag.py:538} INFO - Filling up the DagBag from /opt/airflow/dags/etl_process.py
[2025-01-20T14:46:07.899+0000] {logging_mixin.py:188} INFO - [2025-01-20T14:46:07.892+0000] {dagbag.py:348} ERROR - Failed to import: /opt/airflow/dags/etl_process.py
Traceback (most recent call last):
  File "/home/airflow/.local/lib/python3.8/site-packages/airflow/models/dagbag.py", line 344, in parse
    loader.exec_module(new_module)
  File "<frozen importlib._bootstrap_external>", line 843, in exec_module
  File "<frozen importlib._bootstrap>", line 219, in _call_with_frames_removed
  File "/opt/airflow/dags/etl_process.py", line 1, in <module>
    from datetime import datetime, timedate
ImportError: cannot import name 'timedate' from 'datetime' (/usr/local/lib/python3.8/datetime.py)
[2025-01-20T14:46:07.902+0000] {processor.py:842} WARNING - No viable dags retrieved from /opt/airflow/dags/etl_process.py
[2025-01-20T14:46:07.943+0000] {processor.py:183} INFO - Processing /opt/airflow/dags/etl_process.py took 0.087 seconds
[2025-01-20T14:46:38.554+0000] {processor.py:161} INFO - Started process (PID=17628) to work on /opt/airflow/dags/etl_process.py
[2025-01-20T14:46:38.556+0000] {processor.py:830} INFO - Processing file /opt/airflow/dags/etl_process.py for tasks to queue
[2025-01-20T14:46:38.562+0000] {logging_mixin.py:188} INFO - [2025-01-20T14:46:38.561+0000] {dagbag.py:538} INFO - Filling up the DagBag from /opt/airflow/dags/etl_process.py
[2025-01-20T14:46:38.596+0000] {logging_mixin.py:188} INFO - [2025-01-20T14:46:38.590+0000] {dagbag.py:348} ERROR - Failed to import: /opt/airflow/dags/etl_process.py
Traceback (most recent call last):
  File "/home/airflow/.local/lib/python3.8/site-packages/airflow/models/dagbag.py", line 344, in parse
    loader.exec_module(new_module)
  File "<frozen importlib._bootstrap_external>", line 843, in exec_module
  File "<frozen importlib._bootstrap>", line 219, in _call_with_frames_removed
  File "/opt/airflow/dags/etl_process.py", line 1, in <module>
    from datetime import datetime, timedate
ImportError: cannot import name 'timedate' from 'datetime' (/usr/local/lib/python3.8/datetime.py)
[2025-01-20T14:46:38.599+0000] {processor.py:842} WARNING - No viable dags retrieved from /opt/airflow/dags/etl_process.py
[2025-01-20T14:46:38.636+0000] {processor.py:183} INFO - Processing /opt/airflow/dags/etl_process.py took 0.089 seconds
[2025-01-20T14:47:08.834+0000] {processor.py:161} INFO - Started process (PID=17684) to work on /opt/airflow/dags/etl_process.py
[2025-01-20T14:47:08.836+0000] {processor.py:830} INFO - Processing file /opt/airflow/dags/etl_process.py for tasks to queue
[2025-01-20T14:47:08.841+0000] {logging_mixin.py:188} INFO - [2025-01-20T14:47:08.840+0000] {dagbag.py:538} INFO - Filling up the DagBag from /opt/airflow/dags/etl_process.py
[2025-01-20T14:47:08.878+0000] {logging_mixin.py:188} INFO - [2025-01-20T14:47:08.871+0000] {dagbag.py:348} ERROR - Failed to import: /opt/airflow/dags/etl_process.py
Traceback (most recent call last):
  File "/home/airflow/.local/lib/python3.8/site-packages/airflow/models/dagbag.py", line 344, in parse
    loader.exec_module(new_module)
  File "<frozen importlib._bootstrap_external>", line 843, in exec_module
  File "<frozen importlib._bootstrap>", line 219, in _call_with_frames_removed
  File "/opt/airflow/dags/etl_process.py", line 1, in <module>
    from datetime import datetime, timedate
ImportError: cannot import name 'timedate' from 'datetime' (/usr/local/lib/python3.8/datetime.py)
[2025-01-20T14:47:08.881+0000] {processor.py:842} WARNING - No viable dags retrieved from /opt/airflow/dags/etl_process.py
[2025-01-20T14:47:08.917+0000] {processor.py:183} INFO - Processing /opt/airflow/dags/etl_process.py took 0.089 seconds
[2025-01-20T14:47:39.111+0000] {processor.py:161} INFO - Started process (PID=17740) to work on /opt/airflow/dags/etl_process.py
[2025-01-20T14:47:39.113+0000] {processor.py:830} INFO - Processing file /opt/airflow/dags/etl_process.py for tasks to queue
[2025-01-20T14:47:39.115+0000] {logging_mixin.py:188} INFO - [2025-01-20T14:47:39.115+0000] {dagbag.py:538} INFO - Filling up the DagBag from /opt/airflow/dags/etl_process.py
[2025-01-20T14:47:39.142+0000] {logging_mixin.py:188} INFO - [2025-01-20T14:47:39.136+0000] {dagbag.py:348} ERROR - Failed to import: /opt/airflow/dags/etl_process.py
Traceback (most recent call last):
  File "/home/airflow/.local/lib/python3.8/site-packages/airflow/models/dagbag.py", line 344, in parse
    loader.exec_module(new_module)
  File "<frozen importlib._bootstrap_external>", line 843, in exec_module
  File "<frozen importlib._bootstrap>", line 219, in _call_with_frames_removed
  File "/opt/airflow/dags/etl_process.py", line 1, in <module>
    from datetime import datetime, timedate
ImportError: cannot import name 'timedate' from 'datetime' (/usr/local/lib/python3.8/datetime.py)
[2025-01-20T14:47:39.145+0000] {processor.py:842} WARNING - No viable dags retrieved from /opt/airflow/dags/etl_process.py
[2025-01-20T14:47:39.196+0000] {processor.py:183} INFO - Processing /opt/airflow/dags/etl_process.py took 0.089 seconds
[2025-01-20T14:48:09.383+0000] {processor.py:161} INFO - Started process (PID=17796) to work on /opt/airflow/dags/etl_process.py
[2025-01-20T14:48:09.384+0000] {processor.py:830} INFO - Processing file /opt/airflow/dags/etl_process.py for tasks to queue
[2025-01-20T14:48:09.387+0000] {logging_mixin.py:188} INFO - [2025-01-20T14:48:09.387+0000] {dagbag.py:538} INFO - Filling up the DagBag from /opt/airflow/dags/etl_process.py
[2025-01-20T14:48:09.411+0000] {logging_mixin.py:188} INFO - [2025-01-20T14:48:09.405+0000] {dagbag.py:348} ERROR - Failed to import: /opt/airflow/dags/etl_process.py
Traceback (most recent call last):
  File "/home/airflow/.local/lib/python3.8/site-packages/airflow/models/dagbag.py", line 344, in parse
    loader.exec_module(new_module)
  File "<frozen importlib._bootstrap_external>", line 843, in exec_module
  File "<frozen importlib._bootstrap>", line 219, in _call_with_frames_removed
  File "/opt/airflow/dags/etl_process.py", line 1, in <module>
    from datetime import datetime, timedate
ImportError: cannot import name 'timedate' from 'datetime' (/usr/local/lib/python3.8/datetime.py)
[2025-01-20T14:48:09.412+0000] {processor.py:842} WARNING - No viable dags retrieved from /opt/airflow/dags/etl_process.py
[2025-01-20T14:48:09.442+0000] {processor.py:183} INFO - Processing /opt/airflow/dags/etl_process.py took 0.065 seconds
[2025-01-20T14:48:39.523+0000] {processor.py:161} INFO - Started process (PID=17852) to work on /opt/airflow/dags/etl_process.py
[2025-01-20T14:48:39.525+0000] {processor.py:830} INFO - Processing file /opt/airflow/dags/etl_process.py for tasks to queue
[2025-01-20T14:48:39.529+0000] {logging_mixin.py:188} INFO - [2025-01-20T14:48:39.528+0000] {dagbag.py:538} INFO - Filling up the DagBag from /opt/airflow/dags/etl_process.py
[2025-01-20T14:48:39.557+0000] {logging_mixin.py:188} INFO - [2025-01-20T14:48:39.549+0000] {dagbag.py:348} ERROR - Failed to import: /opt/airflow/dags/etl_process.py
Traceback (most recent call last):
  File "/home/airflow/.local/lib/python3.8/site-packages/airflow/models/dagbag.py", line 344, in parse
    loader.exec_module(new_module)
  File "<frozen importlib._bootstrap_external>", line 843, in exec_module
  File "<frozen importlib._bootstrap>", line 219, in _call_with_frames_removed
  File "/opt/airflow/dags/etl_process.py", line 1, in <module>
    from datetime import datetime, timedate
ImportError: cannot import name 'timedate' from 'datetime' (/usr/local/lib/python3.8/datetime.py)
[2025-01-20T14:48:39.559+0000] {processor.py:842} WARNING - No viable dags retrieved from /opt/airflow/dags/etl_process.py
[2025-01-20T14:48:39.601+0000] {processor.py:183} INFO - Processing /opt/airflow/dags/etl_process.py took 0.086 seconds
[2025-01-20T14:49:09.982+0000] {processor.py:161} INFO - Started process (PID=17907) to work on /opt/airflow/dags/etl_process.py
[2025-01-20T14:49:09.985+0000] {processor.py:830} INFO - Processing file /opt/airflow/dags/etl_process.py for tasks to queue
[2025-01-20T14:49:09.993+0000] {logging_mixin.py:188} INFO - [2025-01-20T14:49:09.992+0000] {dagbag.py:538} INFO - Filling up the DagBag from /opt/airflow/dags/etl_process.py
[2025-01-20T14:49:10.025+0000] {logging_mixin.py:188} INFO - [2025-01-20T14:49:10.017+0000] {dagbag.py:348} ERROR - Failed to import: /opt/airflow/dags/etl_process.py
Traceback (most recent call last):
  File "/home/airflow/.local/lib/python3.8/site-packages/airflow/models/dagbag.py", line 344, in parse
    loader.exec_module(new_module)
  File "<frozen importlib._bootstrap_external>", line 843, in exec_module
  File "<frozen importlib._bootstrap>", line 219, in _call_with_frames_removed
  File "/opt/airflow/dags/etl_process.py", line 1, in <module>
    from datetime import datetime, timedate
ImportError: cannot import name 'timedate' from 'datetime' (/usr/local/lib/python3.8/datetime.py)
[2025-01-20T14:49:10.028+0000] {processor.py:842} WARNING - No viable dags retrieved from /opt/airflow/dags/etl_process.py
[2025-01-20T14:49:10.076+0000] {processor.py:183} INFO - Processing /opt/airflow/dags/etl_process.py took 0.108 seconds
[2025-01-20T14:49:40.487+0000] {processor.py:161} INFO - Started process (PID=17963) to work on /opt/airflow/dags/etl_process.py
[2025-01-20T14:49:40.491+0000] {processor.py:830} INFO - Processing file /opt/airflow/dags/etl_process.py for tasks to queue
[2025-01-20T14:49:40.498+0000] {logging_mixin.py:188} INFO - [2025-01-20T14:49:40.497+0000] {dagbag.py:538} INFO - Filling up the DagBag from /opt/airflow/dags/etl_process.py
[2025-01-20T14:49:40.570+0000] {logging_mixin.py:188} INFO - [2025-01-20T14:49:40.549+0000] {dagbag.py:348} ERROR - Failed to import: /opt/airflow/dags/etl_process.py
Traceback (most recent call last):
  File "/home/airflow/.local/lib/python3.8/site-packages/airflow/models/dagbag.py", line 344, in parse
    loader.exec_module(new_module)
  File "<frozen importlib._bootstrap_external>", line 843, in exec_module
  File "<frozen importlib._bootstrap>", line 219, in _call_with_frames_removed
  File "/opt/airflow/dags/etl_process.py", line 1, in <module>
    from datetime import datetime, timedate
ImportError: cannot import name 'timedate' from 'datetime' (/usr/local/lib/python3.8/datetime.py)
[2025-01-20T14:49:40.577+0000] {processor.py:842} WARNING - No viable dags retrieved from /opt/airflow/dags/etl_process.py
[2025-01-20T14:49:40.647+0000] {processor.py:183} INFO - Processing /opt/airflow/dags/etl_process.py took 0.169 seconds
[2025-01-20T14:50:02.717+0000] {processor.py:161} INFO - Started process (PID=18004) to work on /opt/airflow/dags/etl_process.py
[2025-01-20T14:50:02.720+0000] {processor.py:830} INFO - Processing file /opt/airflow/dags/etl_process.py for tasks to queue
[2025-01-20T14:50:02.727+0000] {logging_mixin.py:188} INFO - [2025-01-20T14:50:02.726+0000] {dagbag.py:538} INFO - Filling up the DagBag from /opt/airflow/dags/etl_process.py
[2025-01-20T14:50:02.786+0000] {logging_mixin.py:188} INFO - [2025-01-20T14:50:02.778+0000] {dagbag.py:348} ERROR - Failed to import: /opt/airflow/dags/etl_process.py
Traceback (most recent call last):
  File "/home/airflow/.local/lib/python3.8/site-packages/airflow/models/dagbag.py", line 344, in parse
    loader.exec_module(new_module)
  File "<frozen importlib._bootstrap_external>", line 843, in exec_module
  File "<frozen importlib._bootstrap>", line 219, in _call_with_frames_removed
  File "/opt/airflow/dags/etl_process.py", line 1, in <module>
    from datetime import datetime, timedate
ImportError: cannot import name 'timedate' from 'datetime' (/usr/local/lib/python3.8/datetime.py)
[2025-01-20T14:50:02.790+0000] {processor.py:842} WARNING - No viable dags retrieved from /opt/airflow/dags/etl_process.py
[2025-01-20T14:50:02.838+0000] {processor.py:183} INFO - Processing /opt/airflow/dags/etl_process.py took 0.138 seconds
[2025-01-20T14:50:33.006+0000] {processor.py:161} INFO - Started process (PID=18060) to work on /opt/airflow/dags/etl_process.py
[2025-01-20T14:50:33.008+0000] {processor.py:830} INFO - Processing file /opt/airflow/dags/etl_process.py for tasks to queue
[2025-01-20T14:50:33.018+0000] {logging_mixin.py:188} INFO - [2025-01-20T14:50:33.017+0000] {dagbag.py:538} INFO - Filling up the DagBag from /opt/airflow/dags/etl_process.py
[2025-01-20T14:50:33.078+0000] {logging_mixin.py:188} INFO - [2025-01-20T14:50:33.071+0000] {dagbag.py:348} ERROR - Failed to import: /opt/airflow/dags/etl_process.py
Traceback (most recent call last):
  File "/home/airflow/.local/lib/python3.8/site-packages/airflow/models/dagbag.py", line 344, in parse
    loader.exec_module(new_module)
  File "<frozen importlib._bootstrap_external>", line 843, in exec_module
  File "<frozen importlib._bootstrap>", line 219, in _call_with_frames_removed
  File "/opt/airflow/dags/etl_process.py", line 1, in <module>
    from datetime import datetime, timedate
ImportError: cannot import name 'timedate' from 'datetime' (/usr/local/lib/python3.8/datetime.py)
[2025-01-20T14:50:33.082+0000] {processor.py:842} WARNING - No viable dags retrieved from /opt/airflow/dags/etl_process.py
[2025-01-20T14:50:33.167+0000] {processor.py:183} INFO - Processing /opt/airflow/dags/etl_process.py took 0.172 seconds
[2025-01-20T14:50:48.426+0000] {processor.py:161} INFO - Started process (PID=18080) to work on /opt/airflow/dags/etl_process.py
[2025-01-20T14:50:48.432+0000] {processor.py:830} INFO - Processing file /opt/airflow/dags/etl_process.py for tasks to queue
[2025-01-20T14:50:48.439+0000] {logging_mixin.py:188} INFO - [2025-01-20T14:50:48.437+0000] {dagbag.py:538} INFO - Filling up the DagBag from /opt/airflow/dags/etl_process.py
[2025-01-20T14:50:48.556+0000] {logging_mixin.py:188} INFO - [2025-01-20T14:50:48.548+0000] {dagbag.py:348} ERROR - Failed to import: /opt/airflow/dags/etl_process.py
Traceback (most recent call last):
  File "/home/airflow/.local/lib/python3.8/site-packages/airflow/models/dagbag.py", line 344, in parse
    loader.exec_module(new_module)
  File "<frozen importlib._bootstrap_external>", line 843, in exec_module
  File "<frozen importlib._bootstrap>", line 219, in _call_with_frames_removed
  File "/opt/airflow/dags/etl_process.py", line 5, in <module>
    from airflow .configurations import conf
ModuleNotFoundError: No module named 'airflow.configurations'
[2025-01-20T14:50:48.560+0000] {processor.py:842} WARNING - No viable dags retrieved from /opt/airflow/dags/etl_process.py
[2025-01-20T14:50:48.615+0000] {processor.py:183} INFO - Processing /opt/airflow/dags/etl_process.py took 0.207 seconds
[2025-01-20T14:51:19.209+0000] {processor.py:161} INFO - Started process (PID=18136) to work on /opt/airflow/dags/etl_process.py
[2025-01-20T14:51:19.211+0000] {processor.py:830} INFO - Processing file /opt/airflow/dags/etl_process.py for tasks to queue
[2025-01-20T14:51:19.215+0000] {logging_mixin.py:188} INFO - [2025-01-20T14:51:19.214+0000] {dagbag.py:538} INFO - Filling up the DagBag from /opt/airflow/dags/etl_process.py
[2025-01-20T14:51:19.286+0000] {logging_mixin.py:188} INFO - [2025-01-20T14:51:19.280+0000] {dagbag.py:348} ERROR - Failed to import: /opt/airflow/dags/etl_process.py
Traceback (most recent call last):
  File "/home/airflow/.local/lib/python3.8/site-packages/airflow/models/dagbag.py", line 344, in parse
    loader.exec_module(new_module)
  File "<frozen importlib._bootstrap_external>", line 843, in exec_module
  File "<frozen importlib._bootstrap>", line 219, in _call_with_frames_removed
  File "/opt/airflow/dags/etl_process.py", line 5, in <module>
    from airflow .configurations import conf
ModuleNotFoundError: No module named 'airflow.configurations'
[2025-01-20T14:51:19.289+0000] {processor.py:842} WARNING - No viable dags retrieved from /opt/airflow/dags/etl_process.py
[2025-01-20T14:51:19.325+0000] {processor.py:183} INFO - Processing /opt/airflow/dags/etl_process.py took 0.123 seconds
[2025-01-20T14:51:22.974+0000] {processor.py:161} INFO - Started process (PID=18147) to work on /opt/airflow/dags/etl_process.py
[2025-01-20T14:51:22.976+0000] {processor.py:830} INFO - Processing file /opt/airflow/dags/etl_process.py for tasks to queue
[2025-01-20T14:51:22.982+0000] {logging_mixin.py:188} INFO - [2025-01-20T14:51:22.981+0000] {dagbag.py:538} INFO - Filling up the DagBag from /opt/airflow/dags/etl_process.py
[2025-01-20T14:51:23.502+0000] {logging_mixin.py:188} INFO - [2025-01-20T14:51:23.464+0000] {dagbag.py:348} ERROR - Failed to import: /opt/airflow/dags/etl_process.py
Traceback (most recent call last):
  File "/home/airflow/.local/lib/python3.8/site-packages/airflow/models/dagbag.py", line 344, in parse
    loader.exec_module(new_module)
  File "<frozen importlib._bootstrap_external>", line 843, in exec_module
  File "<frozen importlib._bootstrap>", line 219, in _call_with_frames_removed
  File "/opt/airflow/dags/etl_process.py", line 9, in <module>
    'start_date': datetime[2025,1,1],
TypeError: 'type' object is not subscriptable
[2025-01-20T14:51:23.506+0000] {processor.py:842} WARNING - No viable dags retrieved from /opt/airflow/dags/etl_process.py
[2025-01-20T14:51:23.645+0000] {processor.py:183} INFO - Processing /opt/airflow/dags/etl_process.py took 0.682 seconds
[2025-01-20T14:51:54.153+0000] {processor.py:161} INFO - Started process (PID=18203) to work on /opt/airflow/dags/etl_process.py
[2025-01-20T14:51:54.154+0000] {processor.py:830} INFO - Processing file /opt/airflow/dags/etl_process.py for tasks to queue
[2025-01-20T14:51:54.157+0000] {logging_mixin.py:188} INFO - [2025-01-20T14:51:54.157+0000] {dagbag.py:538} INFO - Filling up the DagBag from /opt/airflow/dags/etl_process.py
[2025-01-20T14:51:54.205+0000] {logging_mixin.py:188} INFO - [2025-01-20T14:51:54.198+0000] {dagbag.py:348} ERROR - Failed to import: /opt/airflow/dags/etl_process.py
Traceback (most recent call last):
  File "/home/airflow/.local/lib/python3.8/site-packages/airflow/models/dagbag.py", line 344, in parse
    loader.exec_module(new_module)
  File "<frozen importlib._bootstrap_external>", line 843, in exec_module
  File "<frozen importlib._bootstrap>", line 219, in _call_with_frames_removed
  File "/opt/airflow/dags/etl_process.py", line 9, in <module>
    'start_date': datetime[2025,1,1],
TypeError: 'type' object is not subscriptable
[2025-01-20T14:51:54.207+0000] {processor.py:842} WARNING - No viable dags retrieved from /opt/airflow/dags/etl_process.py
[2025-01-20T14:51:54.237+0000] {processor.py:183} INFO - Processing /opt/airflow/dags/etl_process.py took 0.090 seconds
[2025-01-20T14:52:03.876+0000] {processor.py:161} INFO - Started process (PID=18231) to work on /opt/airflow/dags/etl_process.py
[2025-01-20T14:52:03.878+0000] {processor.py:830} INFO - Processing file /opt/airflow/dags/etl_process.py for tasks to queue
[2025-01-20T14:52:03.882+0000] {logging_mixin.py:188} INFO - [2025-01-20T14:52:03.882+0000] {dagbag.py:538} INFO - Filling up the DagBag from /opt/airflow/dags/etl_process.py
[2025-01-20T14:52:03.993+0000] {processor.py:840} INFO - DAG(s) 'etl_process' retrieved from /opt/airflow/dags/etl_process.py
[2025-01-20T14:52:04.665+0000] {logging_mixin.py:188} INFO - [2025-01-20T14:52:04.664+0000] {override.py:1769} INFO - Created Permission View: can delete on DAG:etl_process
[2025-01-20T14:52:04.700+0000] {logging_mixin.py:188} INFO - [2025-01-20T14:52:04.699+0000] {override.py:1769} INFO - Created Permission View: can edit on DAG:etl_process
[2025-01-20T14:52:04.746+0000] {logging_mixin.py:188} INFO - [2025-01-20T14:52:04.745+0000] {override.py:1769} INFO - Created Permission View: can read on DAG:etl_process
[2025-01-20T14:52:04.748+0000] {logging_mixin.py:188} INFO - [2025-01-20T14:52:04.747+0000] {dag.py:3036} INFO - Sync 1 DAGs
[2025-01-20T14:52:04.843+0000] {logging_mixin.py:188} INFO - [2025-01-20T14:52:04.843+0000] {dag.py:3058} INFO - Creating ORM DAG for etl_process
[2025-01-20T14:52:04.970+0000] {logging_mixin.py:188} INFO - [2025-01-20T14:52:04.969+0000] {dag.py:3823} INFO - Setting next_dagrun for etl_process to 2025-01-01 22:00:00+00:00, run_after=2025-01-02 22:00:00+00:00
[2025-01-20T14:52:05.142+0000] {processor.py:183} INFO - Processing /opt/airflow/dags/etl_process.py took 1.279 seconds
[2025-01-20T14:52:36.842+0000] {processor.py:161} INFO - Started process (PID=18285) to work on /opt/airflow/dags/etl_process.py
[2025-01-20T14:52:36.846+0000] {processor.py:830} INFO - Processing file /opt/airflow/dags/etl_process.py for tasks to queue
[2025-01-20T14:52:36.884+0000] {logging_mixin.py:188} INFO - [2025-01-20T14:52:36.883+0000] {dagbag.py:538} INFO - Filling up the DagBag from /opt/airflow/dags/etl_process.py
[2025-01-20T14:52:37.852+0000] {processor.py:840} INFO - DAG(s) 'etl_process' retrieved from /opt/airflow/dags/etl_process.py
[2025-01-20T14:52:38.920+0000] {logging_mixin.py:188} INFO - [2025-01-20T14:52:38.919+0000] {dag.py:3036} INFO - Sync 1 DAGs
[2025-01-20T14:52:39.225+0000] {logging_mixin.py:188} INFO - [2025-01-20T14:52:39.225+0000] {dag.py:3058} INFO - Creating ORM DAG for etl_process
[2025-01-20T14:52:39.498+0000] {logging_mixin.py:188} INFO - [2025-01-20T14:52:39.486+0000] {dag.py:3823} INFO - Setting next_dagrun for etl_process to 2025-01-01 22:00:00+00:00, run_after=2025-01-02 22:00:00+00:00
[2025-01-20T14:52:39.751+0000] {processor.py:183} INFO - Processing /opt/airflow/dags/etl_process.py took 2.932 seconds
[2025-01-20T14:53:27.895+0000] {processor.py:161} INFO - Started process (PID=18328) to work on /opt/airflow/dags/etl_process.py
[2025-01-20T14:53:27.901+0000] {processor.py:830} INFO - Processing file /opt/airflow/dags/etl_process.py for tasks to queue
[2025-01-20T14:53:27.915+0000] {logging_mixin.py:188} INFO - [2025-01-20T14:53:27.914+0000] {dagbag.py:538} INFO - Filling up the DagBag from /opt/airflow/dags/etl_process.py
[2025-01-20T14:53:28.343+0000] {processor.py:840} INFO - DAG(s) 'etl_process' retrieved from /opt/airflow/dags/etl_process.py
[2025-01-20T14:53:28.420+0000] {logging_mixin.py:188} INFO - [2025-01-20T14:53:28.417+0000] {dag.py:3036} INFO - Sync 1 DAGs
[2025-01-20T14:53:28.514+0000] {logging_mixin.py:188} INFO - [2025-01-20T14:53:28.514+0000] {dag.py:3823} INFO - Setting next_dagrun for etl_process to 2025-01-01 22:00:00+00:00, run_after=2025-01-02 22:00:00+00:00
[2025-01-20T14:53:28.602+0000] {processor.py:183} INFO - Processing /opt/airflow/dags/etl_process.py took 0.751 seconds
[2025-01-20T14:53:41.341+0000] {processor.py:161} INFO - Started process (PID=18360) to work on /opt/airflow/dags/etl_process.py
[2025-01-20T14:53:41.344+0000] {processor.py:830} INFO - Processing file /opt/airflow/dags/etl_process.py for tasks to queue
[2025-01-20T14:53:41.351+0000] {logging_mixin.py:188} INFO - [2025-01-20T14:53:41.349+0000] {dagbag.py:538} INFO - Filling up the DagBag from /opt/airflow/dags/etl_process.py
[2025-01-20T14:53:41.443+0000] {processor.py:840} INFO - DAG(s) 'etl_process' retrieved from /opt/airflow/dags/etl_process.py
[2025-01-20T14:53:41.843+0000] {logging_mixin.py:188} INFO - [2025-01-20T14:53:41.843+0000] {dag.py:3036} INFO - Sync 1 DAGs
[2025-01-20T14:53:41.940+0000] {logging_mixin.py:188} INFO - [2025-01-20T14:53:41.939+0000] {dag.py:3823} INFO - Setting next_dagrun for etl_process to 2025-01-01 22:00:00+00:00, run_after=2025-01-02 22:00:00+00:00
[2025-01-20T14:53:42.052+0000] {processor.py:183} INFO - Processing /opt/airflow/dags/etl_process.py took 0.722 seconds
[2025-01-20T14:54:13.295+0000] {processor.py:161} INFO - Started process (PID=18419) to work on /opt/airflow/dags/etl_process.py
[2025-01-20T14:54:13.326+0000] {processor.py:830} INFO - Processing file /opt/airflow/dags/etl_process.py for tasks to queue
[2025-01-20T14:54:13.343+0000] {logging_mixin.py:188} INFO - [2025-01-20T14:54:13.342+0000] {dagbag.py:538} INFO - Filling up the DagBag from /opt/airflow/dags/etl_process.py
[2025-01-20T14:54:13.914+0000] {processor.py:840} INFO - DAG(s) 'etl_process' retrieved from /opt/airflow/dags/etl_process.py
[2025-01-20T14:54:14.114+0000] {logging_mixin.py:188} INFO - [2025-01-20T14:54:14.113+0000] {dag.py:3036} INFO - Sync 1 DAGs
[2025-01-20T14:54:14.348+0000] {logging_mixin.py:188} INFO - [2025-01-20T14:54:14.347+0000] {dag.py:3823} INFO - Setting next_dagrun for etl_process to 2025-01-16 22:00:00+00:00, run_after=2025-01-17 22:00:00+00:00
[2025-01-20T14:54:14.483+0000] {processor.py:183} INFO - Processing /opt/airflow/dags/etl_process.py took 1.207 seconds
[2025-01-20T14:54:45.163+0000] {processor.py:161} INFO - Started process (PID=18474) to work on /opt/airflow/dags/etl_process.py
[2025-01-20T14:54:45.166+0000] {processor.py:830} INFO - Processing file /opt/airflow/dags/etl_process.py for tasks to queue
[2025-01-20T14:54:45.175+0000] {logging_mixin.py:188} INFO - [2025-01-20T14:54:45.175+0000] {dagbag.py:538} INFO - Filling up the DagBag from /opt/airflow/dags/etl_process.py
[2025-01-20T14:54:45.252+0000] {processor.py:840} INFO - DAG(s) 'etl_process' retrieved from /opt/airflow/dags/etl_process.py
[2025-01-20T14:54:45.295+0000] {logging_mixin.py:188} INFO - [2025-01-20T14:54:45.295+0000] {dag.py:3036} INFO - Sync 1 DAGs
[2025-01-20T14:54:45.360+0000] {logging_mixin.py:188} INFO - [2025-01-20T14:54:45.358+0000] {dag.py:3823} INFO - Setting next_dagrun for etl_process to 2025-01-16 22:00:00+00:00, run_after=2025-01-17 22:00:00+00:00
[2025-01-20T14:54:45.434+0000] {processor.py:183} INFO - Processing /opt/airflow/dags/etl_process.py took 0.288 seconds
[2025-01-20T14:55:16.077+0000] {processor.py:161} INFO - Started process (PID=18530) to work on /opt/airflow/dags/etl_process.py
[2025-01-20T14:55:16.080+0000] {processor.py:830} INFO - Processing file /opt/airflow/dags/etl_process.py for tasks to queue
[2025-01-20T14:55:16.084+0000] {logging_mixin.py:188} INFO - [2025-01-20T14:55:16.083+0000] {dagbag.py:538} INFO - Filling up the DagBag from /opt/airflow/dags/etl_process.py
[2025-01-20T14:55:16.145+0000] {processor.py:840} INFO - DAG(s) 'etl_process' retrieved from /opt/airflow/dags/etl_process.py
[2025-01-20T14:55:16.179+0000] {logging_mixin.py:188} INFO - [2025-01-20T14:55:16.179+0000] {dag.py:3036} INFO - Sync 1 DAGs
[2025-01-20T14:55:16.229+0000] {logging_mixin.py:188} INFO - [2025-01-20T14:55:16.228+0000] {dag.py:3823} INFO - Setting next_dagrun for etl_process to 2025-01-19 22:00:00+00:00, run_after=2025-01-20 22:00:00+00:00
[2025-01-20T14:55:16.268+0000] {processor.py:183} INFO - Processing /opt/airflow/dags/etl_process.py took 0.197 seconds
[2025-01-20T14:55:46.666+0000] {processor.py:161} INFO - Started process (PID=18586) to work on /opt/airflow/dags/etl_process.py
[2025-01-20T14:55:46.669+0000] {processor.py:830} INFO - Processing file /opt/airflow/dags/etl_process.py for tasks to queue
[2025-01-20T14:55:46.673+0000] {logging_mixin.py:188} INFO - [2025-01-20T14:55:46.672+0000] {dagbag.py:538} INFO - Filling up the DagBag from /opt/airflow/dags/etl_process.py
[2025-01-20T14:55:46.762+0000] {processor.py:840} INFO - DAG(s) 'etl_process' retrieved from /opt/airflow/dags/etl_process.py
[2025-01-20T14:55:46.806+0000] {logging_mixin.py:188} INFO - [2025-01-20T14:55:46.805+0000] {dag.py:3036} INFO - Sync 1 DAGs
[2025-01-20T14:55:46.881+0000] {logging_mixin.py:188} INFO - [2025-01-20T14:55:46.880+0000] {dag.py:3823} INFO - Setting next_dagrun for etl_process to 2025-01-19 22:00:00+00:00, run_after=2025-01-20 22:00:00+00:00
[2025-01-20T14:55:46.939+0000] {processor.py:183} INFO - Processing /opt/airflow/dags/etl_process.py took 0.280 seconds
[2025-01-20T14:56:17.492+0000] {processor.py:161} INFO - Started process (PID=18642) to work on /opt/airflow/dags/etl_process.py
[2025-01-20T14:56:17.493+0000] {processor.py:830} INFO - Processing file /opt/airflow/dags/etl_process.py for tasks to queue
[2025-01-20T14:56:17.496+0000] {logging_mixin.py:188} INFO - [2025-01-20T14:56:17.496+0000] {dagbag.py:538} INFO - Filling up the DagBag from /opt/airflow/dags/etl_process.py
[2025-01-20T14:56:17.554+0000] {processor.py:840} INFO - DAG(s) 'etl_process' retrieved from /opt/airflow/dags/etl_process.py
[2025-01-20T14:56:17.588+0000] {logging_mixin.py:188} INFO - [2025-01-20T14:56:17.588+0000] {dag.py:3036} INFO - Sync 1 DAGs
[2025-01-20T14:56:17.634+0000] {logging_mixin.py:188} INFO - [2025-01-20T14:56:17.633+0000] {dag.py:3823} INFO - Setting next_dagrun for etl_process to 2025-01-19 22:00:00+00:00, run_after=2025-01-20 22:00:00+00:00
[2025-01-20T14:56:17.672+0000] {processor.py:183} INFO - Processing /opt/airflow/dags/etl_process.py took 0.185 seconds
