[2025-01-23T09:46:29.452+0000] {scheduler_job_runner.py:781} ERROR - Executor reports task instance <TaskInstance: etl_process.start_dag manual__2025-01-23T09:46:28.503906+00:00 [queued]> finished (failed) although the task says it's queued. (Info: None) Was the task killed externally?
